<?xml version="1.0" encoding="utf-8"?>
<!-- =================================================================================== -->
<!-- |    This document was autogenerated by xacro from src/segbot_bu/segbot_bu_description/robots/segbot_bu.urdf.xacro | -->
<!-- |    EDITING THIS FILE BY HAND IS NOT RECOMMENDED                                 | -->
<!-- =================================================================================== -->
<robot name="segbot_bu" xmlns:controller="http://playerstage.sourceforge.net/gazebo/xmlschema/#controller" xmlns:interface="http://playerstage.sourceforge.net/gazebo/xmlschema/#interface" xmlns:sensor="http://playerstage.sourceforge.net/gazebo/xmlschema/#sensor">
  <!-- inches -->
  <!-- inches -->
  <!-- colors -->
  <material name="light_grey">
    <color rgba="0.7 0.7 0.7 1"/>
  </material>
  <material name="dark_grey">
    <color rgba="0.5 0.5 0.5 1"/>
  </material>
  <material name="black">
    <color rgba="0 0 0 1"/>
  </material>
  <material name="almost_black">
    <color rgba="0.02 0.02 0.02 1"/>
  </material>
  <!-- inches -->
  <!-- <gazebo> -->
  <!--   <plugin name="gazebo_ros_control" filename="libgazebo_ros_control.so"> -->
  <!--     <robotNamespace>/</robotNamespace> -->
  <!--   </plugin> -->
  <!-- </gazebo> -->
  <!-- Base footprint is the center of the robot's chassis between the motors projected on the ground -->
  <link name="base_footprint"/>
  <!-- base_link is another name for base_footprint, Another name for the ground projection that is used in all segbot codebase -->
  <link name="base_link"/>
  <joint name="base_footprint_joint" type="fixed">
    <parent link="base_footprint"/>
    <child link="base_link"/>
  </joint>
  <joint name="base_chassis_joint" type="fixed">
    <origin rpy="0 0 0" xyz="0 0 0.15801795"/>
    <parent link="base_link"/>
    <child link="base_chassis_link"/>
  </joint>
  <link name="base_chassis_link">
    <visual>
      <geometry>
        <mesh filename="package://segway_description/meshes/visual/std_gearbox_chassis.dae"/>
      </geometry>
    </visual>
  </link>
  <link name="inertial_collision_link">
    <inertial>
      <mass value="36.914402"/>
      <origin xyz="-0.043407 0.000037 0.060079"/>
      <inertia ixx="1.182744" ixy="0.017957" ixz="-0.077476" iyx="0.017957" iyy="0.538664" iyz="0.000018" izx="-0.077476" izy="0.000018" izz="1.240229"/>
    </inertial>
    <collision>
      <geometry>
        <mesh filename="package://segway_description/meshes/collision/RMP210_chassis_collision.stl"/>
      </geometry>
    </collision>
  </link>
  <joint name="inertial_collision_joint" type="fixed">
    <parent link="base_chassis_link"/>
    <child link="inertial_collision_link"/>
  </joint>
  <joint name="left_spacer_joint" type="fixed">
    <origin rpy="0 0 0" xyz="0 0.19582 0.00665015"/>
    <parent link="base_chassis_link"/>
    <child link="left_spacer_link"/>
  </joint>
  <link name="left_spacer_link">
    <visual>
      <geometry>
        <mesh filename="package://segway_description/meshes/visual/single_spacer.dae"/>
      </geometry>
    </visual>
  </link>
  <joint name="right_spacer_joint" type="fixed">
    <origin rpy="0 0 3.14159" xyz="0 -0.19582 0.00665015"/>
    <parent link="base_chassis_link"/>
    <child link="right_spacer_link"/>
  </joint>
  <link name="right_spacer_link">
    <visual>
      <geometry>
        <mesh filename="package://segway_description/meshes/visual/single_spacer.dae"/>
      </geometry>
    </visual>
  </link>
  <joint name="mcu_1_battery_joint" type="fixed">
    <origin rpy="0 0 0" xyz="-0.09298 0 0"/>
    <parent link="base_chassis_link"/>
    <child link="mcu_1_battery_link"/>
  </joint>
  <link name="mcu_1_battery_link">
    <visual>
      <geometry>
        <mesh filename="package://segway_description/meshes/visual/battery.dae"/>
      </geometry>
    </visual>
  </link>
  <joint name="aux_battery_joint" type="fixed">
    <origin rpy="0 0 3.14159" xyz="0.09298 0 0"/>
    <parent link="base_chassis_link"/>
    <child link="aux_battery_link"/>
  </joint>
  <link name="aux_battery_link">
    <visual>
      <geometry>
        <mesh filename="package://segway_description/meshes/visual/battery.dae"/>
      </geometry>
    </visual>
  </link>
  <link name="left_wheel_link">
    <inertial>
      <mass value="4.195729"/>
      <origin xyz="0 0 0"/>
      <inertia ixx="0.063680" ixy="0.000000" ixz="0.000000" iyx="0.000000" iyy="0.121410" iyz="0.000000" izx="0.000000" izy="0.000000" izz="0.063680"/>
    </inertial>
    <visual>
      <origin rpy="0 0 0.0" xyz="0 0 0"/>
      <geometry>
        <mesh filename="package://segway_description/meshes/visual/i2_wheel.dae"/>
      </geometry>
    </visual>
    <collision>
      <origin rpy="1.570795 0 0" xyz="0 0 0"/>
      <geometry>
        <cylinder length="0.092249" radius="0.2405681"/>
      </geometry>
    </collision>
  </link>
  <gazebo reference="left_wheel_link">
    <mu1 value="10.0"/>
    <mu2 value="10.0"/>
    <kp value="10000000.0"/>
    <kd value="10.0"/>
    <fdir1 value="1 0 0"/>
    <minDepth>0.003</minDepth>
  </gazebo>
  <joint name="left_wheel" type="continuous">
    <parent link="base_chassis_link"/>
    <child link="left_wheel_link"/>
    <origin rpy="0 0 0" xyz="0 0.2395555 0.08255015"/>
    <axis rpy="0 0 0" xyz="0 1 0"/>
  </joint>
  <transmission name="left_wheel_trans" type="SimpleTransmission">
    <type>transmission_interface/SimpleTransmission</type>
    <actuator name="left_wheel_motor">
      <mechanicalReduction>1</mechanicalReduction>
    </actuator>
    <joint name="left_wheel">
      <hardwareInterface>VelocityJointInterface</hardwareInterface>
    </joint>
  </transmission>
  <link name="right_wheel_link">
    <inertial>
      <mass value="4.195729"/>
      <origin xyz="0 0 0"/>
      <inertia ixx="0.063680" ixy="0.000000" ixz="0.000000" iyx="0.000000" iyy="0.121410" iyz="0.000000" izx="0.000000" izy="0.000000" izz="0.063680"/>
    </inertial>
    <visual>
      <origin rpy="0 0 3.14159" xyz="0 0 0"/>
      <geometry>
        <mesh filename="package://segway_description/meshes/visual/i2_wheel.dae"/>
      </geometry>
    </visual>
    <collision>
      <origin rpy="1.570795 0 0" xyz="0 0 0"/>
      <geometry>
        <cylinder length="0.092249" radius="0.2405681"/>
      </geometry>
    </collision>
  </link>
  <gazebo reference="right_wheel_link">
    <mu1 value="10.0"/>
    <mu2 value="10.0"/>
    <kp value="10000000.0"/>
    <kd value="10.0"/>
    <fdir1 value="1 0 0"/>
    <minDepth>0.003</minDepth>
  </gazebo>
  <joint name="right_wheel" type="continuous">
    <parent link="base_chassis_link"/>
    <child link="right_wheel_link"/>
    <origin rpy="0 0 0" xyz="0 -0.2395555 0.08255015"/>
    <axis rpy="0 0 0" xyz="0 1 0"/>
  </joint>
  <transmission name="right_wheel_trans" type="SimpleTransmission">
    <type>transmission_interface/SimpleTransmission</type>
    <actuator name="right_wheel_motor">
      <mechanicalReduction>1</mechanicalReduction>
    </actuator>
    <joint name="right_wheel">
      <hardwareInterface>VelocityJointInterface</hardwareInterface>
    </joint>
  </transmission>
  <joint name="front_caster_plate_joint" type="fixed">
    <origin rpy="0 0 0" xyz="0.31472057 0 0.02425235"/>
    <parent link="base_chassis_link"/>
    <child link="front_caster_plate_link"/>
  </joint>
  <link name="front_caster_plate_link">
    <inertial>
      <mass value="4.487241"/>
      <origin xyz="0.027375 0 0.016101"/>
      <inertia ixx="0.070527" ixy="0.000000" ixz="-0.001013" iyx="0.000000" iyy="0.010678" iyz="0.000000" izx="-0.001013" izy="0.000000" izz="0.078313"/>
    </inertial>
    <visual>
      <origin rpy="0 0 3.14159" xyz="0 0 0"/>
      <geometry>
        <mesh filename="package://segway_description/meshes/visual/caster_plate.dae"/>
      </geometry>
    </visual>
    <collision>
      <geometry>
        <mesh filename="package://segway_description/meshes/collision/caster_plate_collision.stl"/>
      </geometry>
    </collision>
  </link>
  <link name="front_caster_swivel_link">
    <inertial>
      <mass value="0.579519"/>
      <origin xyz="-0.020596 0.000280 -0.055367"/>
      <inertia ixx="0.001361" ixy="-0.000003" ixz="0.000347" iyx="-0.000003" iyy="0.001287" iyz="-0.000010" izx="0.000347" izy="-0.000010" izz="0.000632"/>
    </inertial>
    <visual>
      <geometry>
        <mesh filename="package://segway_description/meshes/visual/caster_bracket.dae"/>
      </geometry>
    </visual>
    <collision>
      <geometry>
        <mesh filename="package://segway_description/meshes/collision/caster_bracket_collision.stl"/>
      </geometry>
    </collision>
  </link>
  <gazebo reference="front_caster_swivel_link">
    <mu1 value="100.0"/>
    <mu2 value="100.0"/>
    <kp value="10000000.0"/>
    <kd value="1.0"/>
  </gazebo>
  <joint name="front_caster_swivel" type="continuous">
    <parent link="front_caster_plate_link"/>
    <child link="front_caster_swivel_link"/>
    <!--xacro:insert_block name="joint_pose"/-->
    <axis xyz="0 0 1"/>
    <anchor xyz="0 0 0"/>
    <limit effort="0.0" velocity="1000"/>
    <dynamics damping="0.7"/>
  </joint>
  <transmission name="front_caster_swivel_trans" type="SimpleTransmission">
    <type>transmission_interface/SimpleTransmission</type>
    <joint name="front_caster_swivel">
      <hardwareInterface>EffortJointInterface</hardwareInterface>
    </joint>
    <actuator name="front_caster_swivel_motor">
      <hardwareInterface>EffortJointInterface</hardwareInterface>
      <mechanicalReduction>1</mechanicalReduction>
    </actuator>
  </transmission>
  <link name="front_caster_wheel_link">
    <inertial>
      <mass value="1.25"/>
      <origin xyz="0 0 0"/>
      <inertia ixx="0.001442" ixy="0.000000" ixz="0.000000" iyx="0.000000" iyy="0.002493" iyz="0.000000" izx="0.000000" izy="0.000000" izz="0.001442"/>
    </inertial>
    <visual>
      <geometry>
        <mesh filename="package://segway_description/meshes/visual/caster_wheel.dae"/>
      </geometry>
    </visual>
    <collision>
      <origin rpy="1.570795 0 0" xyz="0 0 0"/>
      <geometry>
        <cylinder length="0.050" radius="0.0762"/>
      </geometry>
    </collision>
  </link>
  <gazebo reference="front_caster_wheel_link">
    <mu1 value="100.0"/>
    <mu2 value="100.0"/>
    <kp value="10000000.0"/>
    <kd value="10.0"/>
    <fdir1 value="1 0 0"/>
    <minDepth>0.003</minDepth>
  </gazebo>
  <joint name="front_caster_wheel" type="continuous">
    <parent link="front_caster_swivel_link"/>
    <child link="front_caster_wheel_link"/>
    <origin rpy="0 0 0" xyz="-0.03782 0 -0.10608"/>
    <axis xyz="0 1 0"/>
    <anchor xyz="-0.03782 0 -0.10608"/>
    <limit effort="0.0" velocity="1000"/>
    <dynamics damping="0.2"/>
  </joint>
  <transmission name="front_caster_wheel_trans" type="SimpleTransmission">
    <type>transmission_interface/SimpleTransmission</type>
    <joint name="front_caster_wheel">
      <hardwareInterface>EffortJointInterface</hardwareInterface>
    </joint>
    <actuator name="front_caster_wheel_motor">
      <hardwareInterface>EffortJointInterface</hardwareInterface>
      <mechanicalReduction>1</mechanicalReduction>
    </actuator>
  </transmission>
  <joint name="rear_caster_plate_joint" type="fixed">
    <origin rpy="0 0 0" xyz="-0.31472057 0 0.02425235"/>
    <parent link="base_chassis_link"/>
    <child link="rear_caster_plate_link"/>
  </joint>
  <link name="rear_caster_plate_link">
    <inertial>
      <mass value="4.487241"/>
      <origin xyz="0.027375 0 0.016101"/>
      <inertia ixx="0.070527" ixy="0.000000" ixz="-0.001013" iyx="0.000000" iyy="0.010678" iyz="0.000000" izx="-0.001013" izy="0.000000" izz="0.078313"/>
    </inertial>
    <visual>
      <origin rpy="0 0 0.0" xyz="0 0 0"/>
      <geometry>
        <mesh filename="package://segway_description/meshes/visual/caster_plate.dae"/>
      </geometry>
    </visual>
    <collision>
      <geometry>
        <mesh filename="package://segway_description/meshes/collision/caster_plate_collision.stl"/>
      </geometry>
    </collision>
  </link>
  <link name="rear_caster_swivel_link">
    <inertial>
      <mass value="0.579519"/>
      <origin xyz="-0.020596 0.000280 -0.055367"/>
      <inertia ixx="0.001361" ixy="-0.000003" ixz="0.000347" iyx="-0.000003" iyy="0.001287" iyz="-0.000010" izx="0.000347" izy="-0.000010" izz="0.000632"/>
    </inertial>
    <visual>
      <geometry>
        <mesh filename="package://segway_description/meshes/visual/caster_bracket.dae"/>
      </geometry>
    </visual>
    <collision>
      <geometry>
        <mesh filename="package://segway_description/meshes/collision/caster_bracket_collision.stl"/>
      </geometry>
    </collision>
  </link>
  <gazebo reference="rear_caster_swivel_link">
    <mu1 value="100.0"/>
    <mu2 value="100.0"/>
    <kp value="10000000.0"/>
    <kd value="1.0"/>
  </gazebo>
  <joint name="rear_caster_swivel" type="continuous">
    <parent link="rear_caster_plate_link"/>
    <child link="rear_caster_swivel_link"/>
    <!--xacro:insert_block name="joint_pose"/-->
    <axis xyz="0 0 1"/>
    <anchor xyz="0 0 0"/>
    <limit effort="0.0" velocity="1000"/>
    <dynamics damping="0.7"/>
  </joint>
  <transmission name="rear_caster_swivel_trans" type="SimpleTransmission">
    <type>transmission_interface/SimpleTransmission</type>
    <joint name="rear_caster_swivel">
      <hardwareInterface>EffortJointInterface</hardwareInterface>
    </joint>
    <actuator name="rear_caster_swivel_motor">
      <hardwareInterface>EffortJointInterface</hardwareInterface>
      <mechanicalReduction>1</mechanicalReduction>
    </actuator>
  </transmission>
  <link name="rear_caster_wheel_link">
    <inertial>
      <mass value="1.25"/>
      <origin xyz="0 0 0"/>
      <inertia ixx="0.001442" ixy="0.000000" ixz="0.000000" iyx="0.000000" iyy="0.002493" iyz="0.000000" izx="0.000000" izy="0.000000" izz="0.001442"/>
    </inertial>
    <visual>
      <geometry>
        <mesh filename="package://segway_description/meshes/visual/caster_wheel.dae"/>
      </geometry>
    </visual>
    <collision>
      <origin rpy="1.570795 0 0" xyz="0 0 0"/>
      <geometry>
        <cylinder length="0.050" radius="0.0762"/>
      </geometry>
    </collision>
  </link>
  <gazebo reference="rear_caster_wheel_link">
    <mu1 value="100.0"/>
    <mu2 value="100.0"/>
    <kp value="10000000.0"/>
    <kd value="10.0"/>
    <fdir1 value="1 0 0"/>
    <minDepth>0.003</minDepth>
  </gazebo>
  <joint name="rear_caster_wheel" type="continuous">
    <parent link="rear_caster_swivel_link"/>
    <child link="rear_caster_wheel_link"/>
    <origin rpy="0 0 0" xyz="-0.03782 0 -0.10608"/>
    <axis xyz="0 1 0"/>
    <anchor xyz="-0.03782 0 -0.10608"/>
    <limit effort="0.0" velocity="1000"/>
    <dynamics damping="0.2"/>
  </joint>
  <transmission name="rear_caster_wheel_trans" type="SimpleTransmission">
    <type>transmission_interface/SimpleTransmission</type>
    <joint name="rear_caster_wheel">
      <hardwareInterface>EffortJointInterface</hardwareInterface>
    </joint>
    <actuator name="rear_caster_wheel_motor">
      <hardwareInterface>EffortJointInterface</hardwareInterface>
      <mechanicalReduction>1</mechanicalReduction>
    </actuator>
  </transmission>
  <link name="worktop_mount_link"/>
  <joint name="worktop_mount_link" type="fixed">
    <origin rpy="0 0 0" xyz="0 0 0.51435"/>
    <parent link="base_chassis_link"/>
    <child link="worktop_mount_link"/>
  </joint>
  <joint name="back_left_vertical_beam_joint" type="fixed">
    <origin rpy="0 0 0" xyz="-0.127 0.1524 0.05715"/>
    <parent link="base_chassis_link"/>
    <child link="back_left_vertical_beam_link"/>
  </joint>
  <link name="back_left_vertical_beam_link">
    <inertial>
      <mass value="0.1"/>
      <inertia ixx="0.01" ixy="0.0" ixz="0.0" iyy="0.01" iyz="0.0" izz="0.01"/>
    </inertial>
    <visual>
      <origin rpy="0 0 0" xyz="0 0 0.2286"/>
      <geometry>
        <box size="0.0254 0.0254 0.4572"/>
      </geometry>
      <material name="light_grey"/>
    </visual>
    <collision>
      <origin rpy="0 0 0" xyz="0 0 0.2286"/>
      <geometry>
        <box size="0.0254 0.0254 0.4572"/>
      </geometry>
    </collision>
  </link>
  <gazebo reference="back_left_vertical_beam_link">
    <material>Gazebo/Grey</material>
    <mu1 value="100.0"/>
    <mu2 value="100.0"/>
    <kp value="1000000.0"/>
    <kd value="1.0"/>
  </gazebo>
  <joint name="front_left_vertical_beam_joint" type="fixed">
    <origin rpy="0 0 0" xyz="0.127 0.1524 0.05715"/>
    <parent link="base_chassis_link"/>
    <child link="front_left_vertical_beam_link"/>
  </joint>
  <link name="front_left_vertical_beam_link">
    <inertial>
      <mass value="0.1"/>
      <inertia ixx="0.01" ixy="0.0" ixz="0.0" iyy="0.01" iyz="0.0" izz="0.01"/>
    </inertial>
    <visual>
      <origin rpy="0 0 0" xyz="0 0 0.2286"/>
      <geometry>
        <box size="0.0254 0.0254 0.4572"/>
      </geometry>
      <material name="light_grey"/>
    </visual>
    <collision>
      <origin rpy="0 0 0" xyz="0 0 0.2286"/>
      <geometry>
        <box size="0.0254 0.0254 0.4572"/>
      </geometry>
    </collision>
  </link>
  <gazebo reference="front_left_vertical_beam_link">
    <material>Gazebo/Grey</material>
    <mu1 value="100.0"/>
    <mu2 value="100.0"/>
    <kp value="1000000.0"/>
    <kd value="1.0"/>
  </gazebo>
  <joint name="back_right_vertical_beam_joint" type="fixed">
    <origin rpy="0 0 0" xyz="-0.127 -0.1524 0.05715"/>
    <parent link="base_chassis_link"/>
    <child link="back_right_vertical_beam_link"/>
  </joint>
  <link name="back_right_vertical_beam_link">
    <inertial>
      <mass value="0.1"/>
      <inertia ixx="0.01" ixy="0.0" ixz="0.0" iyy="0.01" iyz="0.0" izz="0.01"/>
    </inertial>
    <visual>
      <origin rpy="0 0 0" xyz="0 0 0.2286"/>
      <geometry>
        <box size="0.0254 0.0254 0.4572"/>
      </geometry>
      <material name="light_grey"/>
    </visual>
    <collision>
      <origin rpy="0 0 0" xyz="0 0 0.2286"/>
      <geometry>
        <box size="0.0254 0.0254 0.4572"/>
      </geometry>
    </collision>
  </link>
  <gazebo reference="back_right_vertical_beam_link">
    <material>Gazebo/Grey</material>
    <mu1 value="100.0"/>
    <mu2 value="100.0"/>
    <kp value="1000000.0"/>
    <kd value="1.0"/>
  </gazebo>
  <joint name="front_right_vertical_beam_joint" type="fixed">
    <origin rpy="0 0 0" xyz="0.127 -0.1524 0.05715"/>
    <parent link="base_chassis_link"/>
    <child link="front_right_vertical_beam_link"/>
  </joint>
  <link name="front_right_vertical_beam_link">
    <inertial>
      <mass value="0.1"/>
      <inertia ixx="0.01" ixy="0.0" ixz="0.0" iyy="0.01" iyz="0.0" izz="0.01"/>
    </inertial>
    <visual>
      <origin rpy="0 0 0" xyz="0 0 0.2286"/>
      <geometry>
        <box size="0.0254 0.0254 0.4572"/>
      </geometry>
      <material name="light_grey"/>
    </visual>
    <collision>
      <origin rpy="0 0 0" xyz="0 0 0.2286"/>
      <geometry>
        <box size="0.0254 0.0254 0.4572"/>
      </geometry>
    </collision>
  </link>
  <gazebo reference="front_right_vertical_beam_link">
    <material>Gazebo/Grey</material>
    <mu1 value="100.0"/>
    <mu2 value="100.0"/>
    <kp value="1000000.0"/>
    <kd value="1.0"/>
  </gazebo>
  <joint name="worktop_joint" type="fixed">
    <origin rpy="0 0 0" xyz="0 0 0.51435"/>
    <parent link="base_chassis_link"/>
    <child link="worktop_link"/>
  </joint>
  <link name="worktop_link">
    <inertial>
      <mass value="0.1"/>
      <origin rpy="0 0 0" xyz="0 0 0"/>
      <inertia ixx="0.01" ixy="0.0" ixz="0.0" iyy="0.01" iyz="0.0" izz="0.01"/>
    </inertial>
    <visual>
      <origin rpy="0 0 0" xyz="0 0 0.0015875"/>
      <geometry>
        <box size="0.2794 0.3302 0.003175"/>
      </geometry>
      <material name="dark_grey"/>
    </visual>
    <collision>
      <origin rpy="0 0 0" xyz="0 0 0.0015875"/>
      <geometry>
        <box size="0.2794 0.3302 0.003175"/>
      </geometry>
    </collision>
  </link>
  <gazebo reference="worktop_link">
    <material>Gazebo/Grey</material>
    <mu1 value="100.0"/>
    <mu2 value="100.0"/>
    <kp value="1000000.0"/>
    <kd value="1.0"/>
  </gazebo>
  <joint name="laptop_base_plate_joint" type="fixed">
    <origin rpy="0 0 0" xyz="0 0 0"/>
    <parent link="worktop_mount_link"/>
    <child link="laptop_base_plate_link"/>
  </joint>
  <link name="laptop_base_plate_link">
    <inertial>
      <mass value="0.1"/>
      <origin rpy="0 0 0" xyz="0 0 0"/>
      <inertia ixx="0.01" ixy="0.0" ixz="0.0" iyy="0.01" iyz="0.0" izz="0.01"/>
    </inertial>
    <visual>
      <origin rpy="0 0 0" xyz="0 0 0.0015875"/>
      <geometry>
        <box size="0.2794 0.3302 0.003175"/>
      </geometry>
      <material name="dark_grey"/>
    </visual>
    <collision>
      <origin rpy="0 0 0" xyz="0 0 0.0015875"/>
      <geometry>
        <box size="0.2794 0.3302 0.003175"/>
      </geometry>
    </collision>
  </link>
  <gazebo reference="laptop_base_plate_link">
    <material>Gazebo/Grey</material>
    <mu1 value="100.0"/>
    <mu2 value="100.0"/>
    <kp value="1000000.0"/>
    <kd value="1.0"/>
  </gazebo>
  <!-- laptop base -->
  <joint name="laptop_joint" type="fixed">
    <origin rpy="0 0 0" xyz="0 0 0.003175"/>
    <parent link="laptop_base_plate_link"/>
    <child link="laptop_link"/>
  </joint>
  <link name="laptop_link">
    <inertial>
      <mass value="0.1"/>
      <origin rpy="0 0 0" xyz="0 0 0"/>
      <inertia ixx="0.01" ixy="0.0" ixz="0.0" iyy="0.01" iyz="0.0" izz="0.01"/>
    </inertial>
    <visual>
      <origin rpy="0 0 0" xyz="0 0 0.009525"/>
      <geometry>
        <box size="0.2286 0.3048 0.01905"/>
      </geometry>
      <material name="almost_black"/>
    </visual>
    <collision>
      <origin rpy="0 0 0" xyz="0 0 0.009525"/>
      <geometry>
        <box size="0.3048 0.3556 0.01905"/>
      </geometry>
    </collision>
  </link>
  <gazebo reference="laptop_link">
    <material>Gazebo/Grey</material>
    <mu1 value="100.0"/>
    <mu2 value="100.0"/>
    <kp value="1000000.0"/>
    <kd value="1.0"/>
  </gazebo>
  <!-- laptop screen -->
  <joint name="laptop_screen_joint" type="fixed">
    <origin rpy="0 -1.374445625 0" xyz="0.1143 0 0.01905"/>
    <parent link="laptop_link"/>
    <child link="laptop_screen_link"/>
  </joint>
  <link name="laptop_screen_link">
    <inertial>
      <mass value="0.1"/>
      <origin rpy="0 0 0" xyz="0 0 0"/>
      <inertia ixx="0.01" ixy="0.0" ixz="0.0" iyy="0.01" iyz="0.0" izz="0.01"/>
    </inertial>
    <visual>
      <origin rpy="0 0 -1.570795" xyz="0.1143 0 -0.009525"/>
      <geometry>
        <box size="0.3048 0.2286 0.01905"/>
      </geometry>
      <material name="almost_black"/>
    </visual>
    <collision>
      <origin rpy="0 0 0" xyz="0.1524 0 -0.009525"/>
      <geometry>
        <box size="0.3048 0.3556 0.01905"/>
      </geometry>
    </collision>
  </link>
  <gazebo reference="laptop_screen_link">
    <visual>
      <plugin filename="libgazebo_ros_video.so" name="laptop_video_controller">
        <height>120</height>
        <width>160</width>
        <topicName>image</topicName>
      </plugin>
    </visual>
    <material>Gazebo/Grey</material>
    <mu1 value="100.0"/>
    <mu2 value="100.0"/>
    <kp value="1000000.0"/>
    <kd value="1.0"/>
  </gazebo>
  <joint name="sick_tim_mount_joint" type="fixed">
    <parent link="base_chassis_link"/>
    <child link="sick_tim_mount_link"/>
    <origin rpy="0 0 0" xyz="0.32385 0 0.05715"/>
  </joint>
  <!-- z_offset: distance between base plate and laser center (= center of mesh) -->
  <link name="sick_tim_mount_link">
    <inertial>
      <mass value="0.001"/>
      <origin xyz="0 0 0"/>
      <inertia ixx="0.000001" ixy="0.0" ixz="0.0" iyy="0.000001" iyz="0.0" izz="0.000001"/>
    </inertial>
  </link>
  <joint name="sick_tim_joint" type="fixed">
    <parent link="sick_tim_mount_link"/>
    <child link="sick_tim"/>
    <origin rpy="0 0 0" xyz="0 0 0.06296"/>
  </joint>
  <link name="sick_tim">
    <visual>
      <geometry>
        <mesh filename="package://sick_tim/meshes/sick_tim551.stl"/>
      </geometry>
      <material name="blue">
        <color rgba="0 0 1 1"/>
      </material>
    </visual>
    <collision>
      <geometry>
        <mesh filename="package://sick_tim/meshes/sick_tim551.stl"/>
      </geometry>
    </collision>
    <inertial>
      <mass value="0.25"/>
      <origin xyz="0 0 -0.026"/>
      <inertia ixx="0.0002290832417" ixy="0.0" ixz="0.0" iyy="0.0002290832417" iyz="0.0" izz="0.00014999994"/>
    </inertial>
  </link>
  <gazebo reference="sick_tim">
    <material value="Gazebo/Blue"/>
    <sensor name="sick_tim" type="ray">
      <always_on>true</always_on>
      <update_rate>15.0</update_rate>
      <pose>0 0 0 0 0 0</pose>
      <visualize>false</visualize>
      <ray>
        <scan>
          <horizontal>
            <samples>271</samples>
            <resolution>1</resolution>
            <min_angle>-2.357</min_angle>
            <max_angle>2.357</max_angle>
          </horizontal>
        </scan>
        <range>
          <min>0.05</min>
          <max>25.0</max>
          <resolution>0.01</resolution>
        </range>
      </ray>
      <plugin filename="libgazebo_ros_laser.so" name="gazebo_ros_sick_tim_controller">
        <gaussianNoise>0.005</gaussianNoise>
        <alwaysOn>true</alwaysOn>
        <updateRate>15.0</updateRate>
        <topicName>sick_tim/scan</topicName>
        <frameName>sick_tim</frameName>
      </plugin>
    </sensor>
  </gazebo>
  <!-- 
  <gazebo>
    <plugin name="differential_drive_controller" filename="libgazebo_ros_diff_drive.so">
      <updateRate>100</updateRate>
      <leftJoint>left_wheel</leftJoint>
      <rightJoint>right_wheel</rightJoint>
      <rosDebugLevel>na</rosDebugLevel>
      <publishWheelTF>false</publishWheelTF>
      <publishOdomTF>true</publishOdomTF>
      <publishWheelJointState>false</publishWheelJointState>
      <wheelAcceleration>0</wheelAcceleration>
      <odometrySource>world</odometrySource>
      <publishTf>1</publishTf>
      <wheelSeparation>${track}</wheelSeparation>
      <wheelDiameter>${wheel_radius * 2}</wheelDiameter>
      <wheelTorque>20</wheelTorque>
      <commandTopic>cmd_vel</commandTopic>
      <odometryTopic>odom</odometryTopic>
      <odometryFrame>odom</odometryFrame>
      <robotBaseFrame>base_footprint</robotBaseFrame>
    </plugin>
  </gazebo> -->
</robot>

